Workbook

Sheet Budget Summary
A1: Healthcare Network Infrastructure Budget - Alamein International University Project
A3: COST SUMMARY (All prices in Egyptian Pounds - EGP)
A4: Category | B4: Description | C4: Unit Cost (EGP) | D4: Quantity | E4: Subtotal (EGP) | F4: % of Total
A5: Core Network | B5: ISP Router, Firewall, WAN Router | E5: =Details!G7 -> 1237500 | F5: =IF($E$18>0,E5/$E$18,0) -> 0.031529916
A6: Core Switches | B6: Catalyst 3850 Multilayer (2x) | E6: =Details!G10 -> 1435500 | F6: =IF($E$18>0,E6/$E$18,0) -> 0.036574702
A7: Access Switches | B7: Catalyst 2960 (48P & 24P) | E7: =Details!G14 -> 3910500 | F7: =IF($E$18>0,E7/$E$18,0) -> 0.099634533
A8: Server Infrastructure | B8: HP ProLiant, VMware, Storage | E8: =Details!G25 -> 7761600 | F8: =IF($E$18>0,E8/$E$18,0) -> 0.19775563
A9: Voice Infrastructure | B9: VoIP Gateway, IP Phones | E9: =Details!G29 -> 965250 | F9: =IF($E$18>0,E9/$E$18,0) -> 0.024593334
A10: Wireless Infrastructure | B10: WLC, Access Points | E10: =Details!G33 -> 841500 | F10: =IF($E$18>0,E10/$E$18,0) -> 0.021440343
A11: Cloud Services | B11: AWS Platform Components | E11: =Details!G39 -> 617760 | F11: =IF($E$18>0,E11/$E$18,0) -> 0.015739734
A12: Network Cabling | B12: Cat6A, Fiber, Accessories | E12: =Details!G49 -> 3571672.5 | F12: =IF($E$18>0,E12/$E$18,0) -> 0.091001642
A13: End-User Devices | B13: PCs, Laptops, Tablets, Phones | E13: =Details!G60 -> 10470488 | F13: =IF($E$18>0,E13/$E$18,0) -> 0.26677462
A14: Installation & Labor | B14: Engineering, Testing, Training | E14: =Details!G71 -> 2572900 | F14: =IF($E$18>0,E14/$E$18,0) -> 0.065554198
A15: Software Licenses | B15: OS, Security, Management | E15: =Details!G81 -> 5863770 | F15: =IF($E$18>0,E15/$E$18,0) -> 0.14940135
A16: SUBTOTAL - Capital Equipment | E16: =SUM(E5:E11) -> 16769610 | F16: 100%
A17: Implementation Costs | E17: =SUM(E12:E15) -> 22478830
A18: TOTAL CAPITAL EXPENDITURE | E18: =E16+E17 -> 39248440
A20: Annual Operating Costs | E20: =Details!G83 -> 5863770
A22: 5-Year Total Cost of Ownership | E22: =E18+(E20*5) -> 68567290
A24: Exchange Rate Used: | B24: 1 USD = 49.5 EGP

Sheet Details
A1: DETAILED COST BREAKDOWN - Healthcare Network Project
A2: Category | B2: Item | C2: Model/Specifications | D2: Unit Price (USD) | E2: Unit Price (EGP) | F2: Qty | G2: Subtotal (EGP) | H2: Notes
A3: CORE NETWORK EQUIPMENT
A4: ISP Router | B4: Airtel ISP Router | C4: Enterprise gateway | D4: 2500 | E4: =D4*49.5 -> 123750 | F4: 1 | G4: =E4*F4 -> 123750 | H4: Internet connectivity
A5: Perimeter Firewall | B5: Cisco ASA 5505-X | C5: Stateful inspection, DMZ support | D5: 18000 | E5: =D5*49.5 -> 891000 | F5: 1 | G5: =E5*F5 -> 891000 | H5: Security zones & filtering
A6: WAN Router | B6: Cisco 2811 | C6: VoIP support, IOS 15.1 | D6: 4500 | E6: =D6*49.5 -> 222750 | F6: 1 | G6: =E6*F6 -> 222750 | H6: Inter-network routing
B7: Core Network Subtotal | G7: =SUM(G4:G6) -> 1237500
A8: CORE SWITCHES
A9: Core Multilayer Switch | B9: Cisco Catalyst 3850 48-Port | C9: Layer 3, StackPower, 480Gbps | D9: 14500 | E9: =D9*49.5 -> 717750 | F9: 2 | G9: =E9*F9 -> 1435500 | H9: HSRP + EtherChannel
B10: Core Switches Subtotal | G10: =SUM(G9:G9) -> 1435500
A11: ACCESS LAYER SWITCHES
A12: Access Switch 48P | B12: Cisco Catalyst 2960 48-Port | C12: PoE+, 740W budget, Layer 2 | D12: 8500 | E12: =D12*49.5 -> 420750 | F12: 8 | G12: =E12*F12 -> 3366000 | H12: 35th, 36th, 37th floors
A13: Access Switch 24P | B13: Cisco Catalyst 2960 24-Port | C13: PoE+, 370W budget, Layer 2 | D13: 5500 | E13: =D13*49.5 -> 272250 | F13: 2 | G13: =E13*F13 -> 544500 | H13: Smaller departments
B14: Access Switches Subtotal | G14: =SUM(G12:G13) -> 3910500
A15: SERVER INFRASTRUCTURE
A16: Rack Server | B16: HP ProLiant DL380 Gen10 | C16: Xeon Gold, 64GB RAM, RAID | D16: 8500 | E16: =D16*49.5 -> 420750 | F16: 2 | G16: =E16*F16 -> 841500 | H16: Redundant ESXi hosts
A17: Hypervisor License | B17: VMware ESXi | C17: Enterprise Plus per socket | D17: 4500 | E17: =D17*49.5 -> 222750 | F17: 4 | G17: =E17*F17 -> 891000 | H17: 2 servers x 2 sockets
A18: Directory Server | B18: Red Hat Directory Server | C18: LDAP, DNS, DHCP (redundant) | D18: 3500 | E18: =D18*49.5 -> 173250 | F18: 2 | G18: =E18*F18 -> 346500 | H18: Primary + backup
A19: Application Server | B19: Health Information System | C19: Patient records management | D19: 12000 | E19: =D19*49.5 -> 594000 | F19: 1 | G19: =E19*F19 -> 594000 | H19: EMR/EHR system
A20: Email Server | B20: Microsoft Exchange Server | C20: Std Edition, 500 mailboxes | D20: 4200 | E20: =D20*49.5 -> 207900 | F20: 1 | G20: =E20*F20 -> 207900 | H20: Internal communications
A21: File Server | B21: Windows Server 2022 Std | C21: File & print services | D21: 2800 | E21: =D21*49.5 -> 138600 | F21: 1 | G21: =E21*F21 -> 138600 | H21: Centralized storage
A22: Storage Array | B22: NetApp FAS2750 | C22: 24TB usable, dual controller | D22: 35000 | E22: =D22*49.5 -> 1732500 | F22: 2 | G22: =E22*F22 -> 3465000 | H22: Primary + secondary
A23: Server Rack | B23: APC NetShelter SX 42U | C23: PDU, cable management | D23: 2200 | E23: =D23*49.5 -> 108900 | F23: 4 | G23: =E23*F23 -> 435600 | H23: Equipment housing
A24: UPS System | B24: APC Smart-UPS SRT 10kVA | C24: Online double conversion | D24: 8500 | E24: =D24*49.5 -> 420750 | F24: 2 | G24: =E24*F24 -> 841500 | H24: Power protection
B25: Server Infrastructure Subtotal | G25: =SUM(G16:G24) -> 7761600
A26: VOICE INFRASTRUCTURE
A27: Voice Gateway | B27: Cisco Voice Gateway | C27: CUCME, SIP trunk support | D27: 5500 | E27: =D27*49.5 -> 272250 | F27: 1 | G27: =E27*F27 -> 272250 | H27: VoIP management
A28: IP Phones | B28: Cisco IP Phone 7841 | C28: 4-line display, PoE | D28: 280 | E28: =D28*49.5 -> 13860 | F28: 50 | G28: =E28*F28 -> 693000 | H28: Departmental phones
B29: Voice Infrastructure Subtotal | G29: =SUM(G27:G28) -> 965250
A30: WIRELESS INFRASTRUCTURE
A31: Wireless Controller | B31: Cisco 2504 WLC | C31: Centralized AP management | D31: 8500 | E31: =D31*49.5 -> 420750 | F31: 1 | G31: =E31*F31 -> 420750 | H31: VLAN 10 management
A32: Access Points | B32: Cisco Lightweight AP (LAP) | C32: 802.11ac Wave 2, dual-band | D32: 850 | E32: =D32*49.5 -> 42075 | F32: 10 | G32: =E32*F32 -> 420750 | H32: PH-LAP, DOC-LAP, PRO-LAP
B33: Wireless Infrastructure Subtotal | G33: =SUM(G31:G32) -> 841500
A34: CLOUD SERVICES (AWS)
A35: EC2 Instances | B35: AWS EC2 t3.xlarge | C35: 4 vCPU, 16GB RAM (annual) | D35: 2400 | E35: =D35*49.5 -> 118800 | F35: 2 | G35: =E35*F35 -> 237600 | H35: Application hosting
A36: S3 Storage | B36: AWS S3 Standard | C36: 10TB storage (annual) | D36: 2880 | E36: =D36*49.5 -> 142560 | F36: 1 | G36: =E36*F36 -> 142560 | H36: Backup & archive
A37: RDS Database | B37: AWS RDS MySQL | C37: db.r5.large (annual) | D37: 3600 | E37: =D37*49.5 -> 178200 | F37: 1 | G37: =E37*F37 -> 178200 | H37: Relational database
A38: VPN Gateway | B38: AWS Site-to-Site VPN | C38: Encrypted tunnel (annual) | D38: 1200 | E38: =D38*49.5 -> 59400 | F38: 1 | G38: =E38*F38 -> 59400 | H38: Secure connectivity
B39: Cloud Services Subtotal | G39: =SUM(G35:G38) -> 617760
A40: NETWORK CABLING
...

Sheet Cost-Benefit Analysis
A2: EQUIPMENT SELECTION JUSTIFICATION (Based on Project Requirements)
A4: Category | B4: Selected Solution | C4: Alternative Considered | D4: Justification & Cost-Benefit
A6: Perimeter Security | B6: Cisco ASA 5505-X (891,000 EGP) | C6: pfSense (Free) + Hardware (99,000 EGP) | D6: ASA justified for healthcare: (1) Stateful packet inspection critical for PHI protection. (2) Multiple security zones (Inside/DMZ/Outside) as required by project. (3) Proven HIPAA compliance track record. (4) 24/7 TAC support reduces MTTR from days to hours. (5) Integration with Cisco infrastructure. Premium cost (792K difference) offset by preventing single breach (avg 20.2M EGP in healthcare per IBM study).
A8: Core Infrastructure | B8: Cisco Catalyst 3850 (1,435,500 EGP) | C8: HPE Aruba 6300 (1,089,000 EGP) | D8: Catalyst 3850 critical for: (1) HSRP redundancy ensures 99.99% uptime for patient systems. (2) StackPower for power redundancy. (3) Full LACP EtherChannel as specified in design. (4) Native integration with DNA for automation. (5) Healthcare-specific QoS for VoIP (VLAN 99). 346K premium pays off in 18 months through reduced downtime (EMR outage = 480K EGP/hour).
A10: Wireless Controller | B10: Cisco 2504 WLC (420,750 EGP) | C10: UniFi Cloud Key (24,750 EGP) | D10: WLC essential for: (1) Centralized management of 10 LAPs as per topology. (2) VLAN 10 integration for management traffic. (3) Role-based access for clinical vs guest SSIDs. (4) Fast roaming for VoIP handoff. (5) RF optimization for medical device coexistence.
A12: Server Platform | B12: HP ProLiant DL380 Gen10 (841,500 EGP) | C12: Dell PowerEdge R640 (693,000 EGP) | D12: ProLiant chosen for: (1) iLO remote management for off-hours support. (2) Redundant power/cooling for 24/7 operations. (3) VMware ESXi certification (required by design). (4) 4-hour parts replacement for LDAP/DNS/DHCP servers. (5) Smart Array RAID protects patient data. 148K premium justified by preventing single data loss incident (avg 40.4M EGP).
A14: Storage Infrastructure | B14: NetApp FAS2750 (3,465,000 EGP) | C14: Synology RS4021xs+ (445,500 EGP) | D14: NetApp critical for healthcare: (1) Dual controller eliminates single point of failure. (2) SnapMirror replication for DR (primary + secondary as designed). (3) 99.999% uptime SLA for patient records. (4) WORM compliance for regulatory retention. (5) Sub-millisecond latency for EMR queries.
A16: VoIP Infrastructure | B16: Cisco CUCME (272,250 EGP) | C16: 3CX Software PBX (49,500 EGP) | D16: CUCME justified by: (1) VLAN 99 integration as designed. (2) Directory numbers 3000-3020 management per spec. (3) Native integration with 2811 router. (4) Clinical-grade call quality. (5) Emergency services integration.
A18: Structured Cabling | B18: Cat6A (1,732,500 EGP) | C18: Cat6 (990,000 EGP) | D18: Cat6A ROI analysis: (1) 10Gbps to desktop for medical imaging (DICOM files). (2) Future-proof for 20 years vs 10 for Cat6. (3) Better alien crosstalk for 280-drop density. (4) Required for trunk links in hierarchical design.
A21: QUANTIFIED BENEFITS & ROI ANALYSIS (5-Year Projection)
A23: Benefit Category | B23: Annual Value (EGP) | C23: 5-Year Value (EGP) | D23: Calculation Methodology
A24: Reduced Downtime | B24: 4200000 | C24: 21000000 | D24: 99.9% uptime vs 98% baseline = 17.5 hrs saved. Healthcare EMR downtime = 480,000 EGP/hr. Total: 17.5 x 480K = 4.2M EGP annually.
A25: Security Breach Prevention | B25: 5940000 | C25: 29700000 | D25: NGFW + segmentation reduces incidents by 3/year. Average healthcare breach = 2M EGP per incident. 3 x 2M = 5.94M EGP prevented annually.
A26: IT Operational Efficiency | B26: 2376000 | C26: 11880000 | D26: Network automation saves 20 hrs/week. Senior admin at 4,000 EGP/hr. Net after tool costs = 2.38M EGP.
A27: VoIP Cost Avoidance | B27: 1188000 | C27: 5940000 | D27: Replace analog system (1.44M/yr cost). VoIP cost = 252K/yr. Net savings = 1.19M EGP annually.
A28: Bandwidth Optimization | B28: 950400 | C28: 4752000 | D28: Core switching + QoS reduces WAN by 35%. Deferred upgrade saves 79.2K/month x 12 = 950K EGP/year.
A29: Wireless Productivity | B29: 1732500 | C29: 8662500 | D29: WiFi 6 eliminates 5 min/staff/day waiting. 150 staff productivity gain = 1.73M EGP annually.
A30: Data Center Efficiency | B30: 831600 | C30: 4158000 | D30: Virtualization reduces server count from 12 to 2 physical. Power and cooling savings = 832K EGP/year.
A31: Patient Satisfaction | B31: 1732500 | C31: 8662500 | D31: Network reliability improves patient scores by 8%. Revenue impact = 1.73M EGP.
B32: =SUM(B24:B31) -> 18951000 | C32: =B32*5 -> 94755000
A33: TOTAL QUANTIFIED BENEFITS | B33: =SUM(B23:B30) -> 17218500 | C33: =B32*5 -> 94755000 | D33: Sum of all measurable benefits
A35: Capital Investment | B35: ='Budget Summary'!E18 -> 39248440 | D35: From Summary Sheet - Total CapEx
A36: 5-Year Operating Costs | B36: ='Budget Summary'!E20*5 -> 29318850 | D36: Annual licenses & support x 5 years
A37: 5-Year Total Cost | B37: =B35+B36 -> 68567290 | D37: Complete investment over 5 years
A39: NET 5-YEAR BENEFIT | B39: =C32-B37 -> 26187710 | D39: Total Benefits minus Total Costs
A40: Return on Investment | B40: =IF(B37>0,(B39/B37)*100,0) -> 38.192716 | D40: Net benefit as % of investment
A41: Payback Period (Years) | B41: =IF(B32>0,B37/B32,0) -> 3.6181357 | D41: Years to recover full investment
A42: Benefit-Cost Ratio | B42: =IF(B37>0,C32/B37,0) -> 1.3819272 | D42: Benefit per Egyptian Pound invested
A45: RISK MITIGATION VALUE
A47: Risk Factor | B47: Impact Without | C47: Mitigation Strategy | D47: Estimated Value
A48: HIPAA Violation | B48: 7.4M - 74M EGP fine | C48: ASA firewall + VLAN segmentation | D48: Business continuity protection
A49: Ransomware Attack | B49: 45.5M EGP average | C49: DMZ isolation + NGFW + backups | D49: 75% attack surface reduction
A50: Network Outage | B50: 480K EGP per hour | C50: HSRP + redundant power + dual storage | D50: Under 2 hrs downtime annually
A51: Data Loss | B51: 40.4M EGP breach cost | C51: NetApp snapshots + replication | D51: RPO under 15 min
A52: Medical Device Hack | B52: Patient safety risk | C52: IoT VLAN isolation + IPS | D52: Prevents lateral movement
A53: Regulatory Issues | B53: Accreditation loss | C53: Audit logging + encryption | D53: JCI/HIPAA compliance
